{"name": "test_answer", "status": "failed", "statusDetails": {"message": "AssertionError: assert 4 == 5\n +  where 4 = func(3)", "trace": "@pytest.mark.main\n    def test_answer():\n>       assert func(3) == 5\nE       assert 4 == 5\nE        +  where 4 = func(3)\n\ntest_arithmetic.py:10: AssertionError"}, "start": 1691455703880, "stop": 1691455703880, "uuid": "ea10dcbb-731f-4677-a9c3-b12798d04001", "historyId": "e4c2e776d230236f9bb9475bf4f4994c", "testCaseId": "289b61bd6cec3b513cf95a5fdddb0311", "fullName": "test_arithmetic#test_answer", "labels": [{"name": "tag", "value": "main"}, {"name": "suite", "value": "test_arithmetic"}, {"name": "host", "value": "test-users-MacBook-Air.local"}, {"name": "thread", "value": "92021-MainThread"}, {"name": "framework", "value": "pytest"}, {"name": "language", "value": "cpython3"}, {"name": "package", "value": "test_arithmetic"}]}